Workbook

Sheet WBS
B1: MediBook WBS
A2: № | B2: Задача | C2: Type | D2: Iterations | E2: Estimate (hours) | F2: Total days | G2: Rate | H2: Total Price | I2: Notes
B3: Phase 1. BFF | F3: =SUM(F4:F7) -> 9 | H3: =SUM(H4:H7) -> 180000
A4: 1 | B4: Маршруты и сборка ответов, 10 маршрутов, OpenAPI | C4: dev | D4: 1 | E4: 28 | F4: =E4*D4/8 -> 3.5 | G4: =Assumptions!$C$8 -> 2500 | H4: =F4*G4*8 -> 70000
A5: 2 | B5: Проверка JWT и ролей, единый формат ошибок | C5: dev | D5: 1 | E5: 20 | F5: =E5*D5/8 -> 2.5 | G5: =Assumptions!$C$8 -> 2500 | H5: =F5*G5*8 -> 50000 | I5: NFR-03
A6: 3 | B6: Таймауты и rate limit | C6: dev | D6: 1 | E6: 12 | F6: =E6*D6/8 -> 1.5 | G6: =Assumptions!$C$8 -> 2500 | H6: =F6*G6*8 -> 30000 | I6: NFR-05
A7: 4 | B7: API-тесты | C7: tst | D7: 1 | E7: 12 | F7: =E7*D7/8 -> 1.5 | G7: =Assumptions!$C$8 -> 2500 | H7: =F7*G7*8 -> 30000
B8: Phase 2. Appointment Service | F8: =SUM(F9:F18) -> 32 | H8: =SUM(H9:H18) -> 640000
A9: 5 | B9: Модель данных и миграции | C9: dev | D9: 1 | E9: 16 | F9: =E9*D9/8 -> 2 | G9: =Assumptions!$C$8 -> 2500 | H9: =F9*G9*8 -> 40000
A10: 6 | B10: POST /appointments: проверка слота, запись одной транзакцией | C10: dev | D10: 1 | E10: 40 | F10: =E10*D10/8 -> 5 | G10: =Assumptions!$C$8 -> 2500 | H10: =F10*G10*8 -> 100000 | I10: ADR-001
A11: 7 | B11: Idempotency key | C11: dev | D11: 1 | E11: 24 | F11: =E11*D11/8 -> 3 | G11: =Assumptions!$C$8 -> 2500 | H11: =F11*G11*8 -> 60000 | I11: ADR-001
A12: 8 | B12: Статусы записи, отмена | C12: dev | D12: 1 | E12: 32 | F12: =E12*D12/8 -> 4 | G12: =Assumptions!$C$8 -> 2500 | H12: =F12*G12*8 -> 80000 | I12: FR-02
A13: 9 | B13: Outbox и публикация событий | C13: dev | D13: 1 | E13: 32 | F13: =E13*D13/8 -> 4 | G13: =Assumptions!$C$8 -> 2500 | H13: =F13*G13*8 -> 80000 | I13: ADR-002
A14: 10 | B14: Чтение: записи пациента, расписание врача | C14: dev | D14: 1 | E14: 20 | F14: =E14*D14/8 -> 2.5 | G14: =Assumptions!$C$8 -> 2500 | H14: =F14*G14*8 -> 50000 | I14: FR-04
A15: 11 | B15: Пациент видит только свои записи | C15: dev | D15: 1 | E15: 16 | F15: =E15*D15/8 -> 2 | G15: =Assumptions!$C$8 -> 2500 | H15: =F15*G15*8 -> 40000 | I15: NFR-03
A16: 12 | B16: Конкурентный тест: 50 запросов на один слот | C16: tst | D16: 2 | E16: 16 | F16: =E16*D16/8 -> 4 | G16: =Assumptions!$C$8 -> 2500 | H16: =F16*G16*8 -> 80000 | I16: NFR-02, второй прогон после исправлений
A17: 13 | B17: Интеграционные тесты | C17: tst | D17: 1 | E17: 32 | F17: =E17*D17/8 -> 4 | G17: =Assumptions!$C$8 -> 2500 | H17: =F17*G17*8 -> 80000
A18: 14 | B18: Логи и метрики | C18: dev | D18: 1 | E18: 12 | F18: =E18*D18/8 -> 1.5 | G18: =Assumptions!$C$8 -> 2500 | H18: =F18*G18*8 -> 30000 | I18: NFR-06
B19: Phase 3. Schedule Service | F19: =SUM(F20:F30) -> 53 | H19: =SUM(H20:H30) -> 1060000
A20: 15 | B20: Spike: разобраться с External Schedule API | C20: sa | D20: 1 | E20: 40 | F20: =E20*D20/8 -> 5 | G20: =Assumptions!$C$8 -> 2500 | H20: =F20*G20*8 -> 100000 | I20: 5 дней, после него оценка пересматривается
A21: 16 | B21: Модель слотов, CRUD слотов для администратора | C21: dev | D21: 1 | E21: 64 | F21: =E21*D21/8 -> 8 | G21: =Assumptions!$C$8 -> 2500 | H21: =F21*G21*8 -> 160000 | I21: FR-03
A22: 17 | B22: Поиск свободных слотов: чтение с реплики, индексы | C22: dev | D22: 1 | E22: 32 | F22: =E22*D22/8 -> 4 | G22: =Assumptions!$C$8 -> 2500 | H22: =F22*G22*8 -> 80000 | I22: NFR-01
A23: 18 | B23: Redis-кэш слотов и его сброс | C23: dev | D23: 1 | E23: 40 | F23: =E23*D23/8 -> 5 | G23: =Assumptions!$C$8 -> 2500 | H23: =F23*G23*8 -> 100000 | I23: NFR-01
A24: 19 | B24: Адаптер External Schedule API | C24: dev | D24: 1 | E24: 64 | F24: =E24*D24/8 -> 8 | G24: =Assumptions!$C$8 -> 2500 | H24: =F24*G24*8 -> 160000 | I24: оценка до spike
A25: 20 | B25: Синхронизация расписания и сверка | C25: dev | D25: 1 | E25: 48 | F25: =E25*D25/8 -> 6 | G25: =Assumptions!$C$8 -> 2500 | H25: =F25*G25*8 -> 120000 | I25: оценка до spike
A26: 21 | B26: Работа, когда внешний API недоступен | C26: dev | D26: 1 | E26: 24 | F26: =E26*D26/8 -> 3 | G26: =Assumptions!$C$8 -> 2500 | H26: =F26*G26*8 -> 60000 | I26: NFR-05
A27: 22 | B27: Проверка слота для Appointment Service | C27: dev | D27: 1 | E27: 16 | F27: =E27*D27/8 -> 2 | G27: =Assumptions!$C$8 -> 2500 | H27: =F27*G27*8 -> 40000
A28: 23 | B28: Нагрузочный тест поиска, 1000 RPS | C28: tst | D28: 2 | E28: 20 | F28: =E28*D28/8 -> 5 | G28: =Assumptions!$C$8 -> 2500 | H28: =F28*G28*8 -> 100000 | I28: NFR-01, второй прогон после настройки
A29: 24 | B29: Интеграционные тесты с заглушкой внешнего API | C29: tst | D29: 1 | E29: 40 | F29: =E29*D29/8 -> 5 | G29: =Assumptions!$C$8 -> 2500 | H29: =F29*G29*8 -> 100000
A30: 25 | B30: Логи и метрики | C30: dev | D30: 1 | E30: 16 | F30: =E30*D30/8 -> 2 | G30: =Assumptions!$C$8 -> 2500 | H30: =F30*G30*8 -> 40000 | I30: NFR-06
B31: Phase 4. Notification Worker | F31: =SUM(F32:F38) -> 16 | H31: =SUM(H32:H38) -> 320000
A32: 26 | B32: Чтение событий из очереди, защита от дублей | C32: dev | D32: 1 | E32: 20 | F32: =E32*D32/8 -> 2.5 | G32: =Assumptions!$C$8 -> 2500 | H32: =F32*G32*8 -> 50000 | I32: ADR-002
A33: 27 | B33: Шаблоны уведомлений | C33: dev | D33: 1 | E33: 12 | F33: =E33*D33/8 -> 1.5 | G33: =Assumptions!$C$8 -> 2500 | H33: =F33*G33*8 -> 30000 | I33: FR-05
A34: 28 | B34: Отправка SMS и email | C34: dev | D34: 1 | E34: 24 | F34: =E34*D34/8 -> 3 | G34: =Assumptions!$C$8 -> 2500 | H34: =F34*G34*8 -> 60000
A35: 29 | B35: Retry и DLQ | C35: dev | D35: 1 | E35: 24 | F35: =E35*D35/8 -> 3 | G35: =Assumptions!$C$8 -> 2500 | H35: =F35*G35*8 -> 60000 | I35: ADR-002
A36: 30 | B36: Журнал доставки | C36: dev | D36: 1 | E36: 12 | F36: =E36*D36/8 -> 1.5 | G36: =Assumptions!$C$8 -> 2500 | H36: =F36*G36*8 -> 30000
A37: 31 | B37: Тесты с заглушкой провайдера | C37: tst | D37: 1 | E37: 24 | F37: =E37*D37/8 -> 3 | G37: =Assumptions!$C$8 -> 2500 | H37: =F37*G37*8 -> 60000
A38: 32 | B38: Метрики очереди и DLQ | C38: dev | D38: 1 | E38: 12 | F38: =E38*D38/8 -> 1.5 | G38: =Assumptions!$C$8 -> 2500 | H38: =F38*G38*8 -> 30000 | I38: NFR-06
B39: Phase 5. Audit Service | F39: =SUM(F40:F47) -> 19 | H39: =SUM(H40:H47) -> 380000
A40: 33 | B40: Модель события и API записи | C40: dev | D40: 1 | E40: 16 | F40: =E40*D40/8 -> 2 | G40: =Assumptions!$C$8 -> 2500 | H40: =F40*G40*8 -> 40000
...

Sheet Assumptions
A1: Assumption | B1: Description | C1: Value
A2: A1 | B2: Оцениваю пять компонентов: BFF, Appointment Service, Schedule Service, Notification Worker, Audit Service. UI, инфраструктура и подключение к Auth Provider сюда не входят.
A3: A2 | B3: Команда: архитектор (частично), 2 backend-разработчика, 1 QA.
A4: A3 | B4: Стек: Java 21, Spring Boot, PostgreSQL, Redis, RabbitMQ.
A5: A4 | B5: Задача готова, когда есть код, тесты и выкладка на staging.
A6: A5 | B6: 1 день = 8 часов. Total days = Estimate × Iterations / 8.
A7: A6 | B7: Type: sa — архитектор, dev — разработчик, tst — QA.
A8: A7 | B8: Ставка, руб/час. Условная, чтобы понять порядок суммы. | C8: 2500
A9: A8 | B9: Шкала T-shirt в днях: S до 10, M 11–25, L 26–50, XL больше 50.
A10: A9 | B10: Клиника в первую неделю даёт доступ к тестовому External Schedule API.

Sheet Requirements
A1: ID | B1: Requirement | C1: Где учтено в оценке
A2: FR-01 | B2: Пациент может записаться на свободный слот | C2: Appointment Service, BFF
A3: FR-02 | B3: Пациент может отменить запись | C3: Appointment Service, Notification Worker
A4: FR-03 | B4: Администратор управляет слотами расписания | C4: Schedule Service, Audit Service
A5: FR-04 | B5: Врач видит своё расписание | C5: Appointment Service, BFF
A6: FR-05 | B6: Система отправляет уведомления о записи и её изменениях | C6: Notification Worker, outbox в Appointment Service
A7: FR-06 | B7: Действия администраторов пишутся в журнал аудита | C7: Audit Service
A8: NFR-01 | B8: Поиск слотов: p95 < 2 с в пик | C8: Schedule Service: кэш, реплика, нагрузочный тест
A9: NFR-02 | B9: Нет двойной записи на слот | C9: Appointment Service: транзакция, уникальный индекс, конкурентный тест
A10: NFR-03 | B10: Доступ по ролям, защита персональных данных | C10: BFF, Appointment Service, Audit Service
A11: NFR-04 | B11: Критические действия попадают в неизменяемый аудит-лог | C11: Audit Service
A12: NFR-05 | B12: Запись доступна в рабочее время клиники | C12: BFF, Schedule Service, Notification Worker
A13: NFR-06 | B13: Логи, метрики, трейсы | C13: Строка «Логи и метрики» в каждой фазе

Sheet Risks
A1: Risk | B1: Impact (hours) | C1: Probability | D1: Mitigation | E1: Impact × Probability (hours)
A2: R-01. External Schedule API работает не так, как в документации: переделка адаптера и синхронизации | B2: 160 | C2: 0.6 | D2: Spike 5 дней до начала работ | E2: =B2*C2 -> 96
A3: R-02. Конкурентный тест находит двойную запись после второго прогона | B3: 40 | C3: 0.4 | D3: Тест в начале работ по Appointment Service | E3: =B3*C3 -> 16
A4: R-03. Меняется ролевая модель, проверки доступа надо переделывать | B4: 80 | C4: 0.4 | D4: Согласовать роли с клиникой до старта | E4: =B4*C4 -> 32
A5: R-04. Поиск слотов не укладывается в 2 с после второго нагрузочного прогона | B5: 80 | C5: 0.4 | D5: Нагрузочный тест сразу, как готов поиск с кэшем | E5: =B5*C5 -> 32
A6: R-05. SMS-провайдер ограничивает отправку, нужен второй канал | B6: 40 | C6: 0.6 | D6: Выбрать провайдера до начала работ, заглушка с отказами | E6: =B6*C6 -> 24
A7: Total | B7: =SUM(B2:B6) -> 400 | E7: =SUM(E2:E6) -> 200

Sheet Deliverables
A1: Phase | B1: Delivery
A2: Phase 1 | B2: BFF: 10 маршрутов, OpenAPI, отчёт API-тестов
A3: Phase 2 | B3: Appointment Service: запись и отмена, отчёт конкурентного теста
A4: Phase 3 | B4: Schedule Service: результат spike, поиск слотов с кэшем, адаптер внешнего API, отчёт нагрузочного теста
A5: Phase 4 | B5: Notification Worker: SMS и email с retry и DLQ
A6: Phase 5 | B6: Audit Service: журнал и API чтения
